<?xml version="1.0"?>
<robot xmlns:xacro="http://www.ros.org/wiki/xacro" >

    <xacro:include filename="$(find robolaunch_cloudy_description)/urdf/inertial_macros.xacro"/>
    <xacro:include filename="$(find robolaunch_cloudy_description)/sensors/generic_laser.urdf.xacro" />
    <xacro:include filename="$(find robolaunch_cloudy_description)/urdf/robots/cloudy_v1_properties.urdf.xacro" />
    <xacro:include filename="$(find robolaunch_cloudy_description)/sensors/depth_sensor.urdf.xacro" />
    <xacro:property name="depth_sensor_pose">
        <origin xyz="0.4 0 0.05" rpy="0 0 0"/>
    </xacro:property>

   <xacro:property name="scale_ratio" value="0.0015" />
   <link name="base_footprint"/>

    <material name="white">
        <color rgba="1 1 1 1" />
    </material>

    <material name="orange">
        <color rgba="1 0.3 0.1 1"/>
    </material>

    <material name="blue">
        <color rgba="0.2 0.2 1 1"/>
    </material>

    <material name="black">
        <color rgba="0 0 0 1"/>
    </material>
  <material name="gray">
        <color rgba="0.3 0.3 0.3 1"/>
    </material>
    
    <!-- BASE LINK -->

    <link name="base_link">

    </link>

    <joint name="base_to_footprint" type="fixed">
      <parent link="base_footprint"/>
      <child link="base_link"/>
      <origin xyz="0 0 0.035" rpy="0 0 0"/>
    </joint>


    <!-- CHASSIS LINK -->

    <joint name="chassis_joint" type="fixed">
        <parent link="base_link"/>
        <child link="chassis"/>
        <origin xyz="-0.1 0 0"/>
    </joint>

    <link name="chassis">
        <visual>
            <origin xyz="0 0.15 0" rpy="1.57 0 0"/>
            <geometry>
                <mesh scale="${scale_ratio} ${scale_ratio} ${scale_ratio}" filename="file://$(find robolaunch_cloudy_description)/urdf/meshes/body.stl"/>
            </geometry>
            <material name="gray"/>
        </visual>
        <collision>
            <origin xyz="0.25 0 0.075"/>
            <geometry>
                <box size="0.5 0.3 0.15"/>
            </geometry>
        </collision>
        <xacro:inertial_box mass="0.5" x="0.3" y="0.3" z="0.15">
            <origin xyz="0.15 0 0.075" rpy="0 0 0"/>
        </xacro:inertial_box>
    </link>
    <gazebo reference="chassis">
    <material>Gazebo/DarkGrey</material>
      <mu1>0.2</mu1>
      <mu2>0.2</mu2>

    </gazebo>
    
    <!-- LEFT WHEEL LINK -->

    <joint name="left_wheel_joint" type="continuous">
        <parent link="base_link"/>
        <child link="left_wheel"/>
        <origin xyz="0.145 0.14 0.048" rpy="-${pi/2} 0 0" />
        <axis xyz="0 0 1"/>
    </joint>

    <link name="right_wheel">
        <visual>
            <geometry>
                <mesh scale="${scale_ratio} ${scale_ratio} ${scale_ratio}" filename="file://$(find robolaunch_cloudy_description)/urdf/meshes/wheel.stl" />
            </geometry>
            <material name="white"/>
            <origin xyz="-0.049 -0.049 0" rpy="0 ${pi/2} 0" />

        </visual>
        <collision>
            <geometry>
                <cylinder radius="0.05" length="0.04"/>
            </geometry>
        </collision>
        <xacro:inertial_cylinder mass="0.1" length="0.04" radius="0.05">
            <origin xyz="0 0 0" rpy="0 0 0"/>
        </xacro:inertial_cylinder>
    </link>
    <gazebo reference="left_wheel">
    <material>Gazebo/White</material>
    </gazebo>
    <!-- RIGHT WHEEL LINK -->

    <joint name="right_wheel_joint" type="continuous">
        <parent link="base_link"/>
        <child link="right_wheel"/>
        <origin xyz="0.145 -0.14 0.048" rpy="-${pi/2} 0 0" />
        <axis xyz="0 0 1"/>
    </joint>

    <link name="left_wheel">
        <visual>
            <geometry>
                <mesh scale="${scale_ratio} ${scale_ratio} ${scale_ratio}" filename="file://$(find robolaunch_cloudy_description)/urdf/meshes/wheel.stl" />
            </geometry>
            <origin xyz="-0.049 -0.049 0" rpy="0 ${pi/2} 0" />
            <material name="white"/>
        </visual>
        <collision>
            <geometry>
                <cylinder radius="0.05" length="0.04"/>
            </geometry>
        </collision>
        <xacro:inertial_cylinder mass="0.1" length="0.04" radius="0.05">
            <origin xyz="0 0 0" rpy="0 0 0"/>
        </xacro:inertial_cylinder>
    </link>
    <gazebo reference="right_wheel">
    <material>Gazebo/White</material>
    </gazebo>


    <!-- CASTER WHEEL LINK -->

  <!--  <joint name="caster_wheel_joint" type="fixed">
        <parent link="chassis"/>
        <child link="caster_wheel"/>
        <origin xyz="0.24 0 0"/>
    </joint>

    <joint name="caster_wheel_joint2" type="fixed">
        <parent link="chassis"/>
        <child link="caster_wheel2"/>
        <origin xyz="0.06 0 0"/>
    </joint>


    <link name="caster_wheel">
        <visual>
            <geometry>
                <sphere radius="0.04"/>
            </geometry>
            <material name="black"/>
        </visual>
        <collision>
            <geometry>
                <sphere radius="0.05"/>
            </geometry>
        </collision>
        <xacro:inertial_sphere mass="0.1" radius="0.04">
            <origin xyz="0 0 0" rpy="0 0 0"/>
        </xacro:inertial_sphere>
    </link>

    <link name="caster_wheel2">
        <visual>
            <geometry>
                <sphere radius="0.04"/>
            </geometry>
            <material name="black"/>
        </visual>
        <collision>
            <geometry>
                <sphere radius="0.05"/>
            </geometry>
        </collision>
        <xacro:inertial_sphere mass="0.1" radius="0.04">
            <origin xyz="0 0 0" rpy="0 0 0"/>
        </xacro:inertial_sphere>
    </link>
    -->
</robot>